/usr/lib/python3.4/site-packages/deap/tools/_hypervolume/pyhv.py:33: ImportWarning: Falling back to the python version of hypervolume module. Expect this to be very slow.
  "module. Expect this to be very slow.", ImportWarning)
Tipos: [1, 1, 1, 2, 1, 1, 1], rangos: [1, 2, 2, 2, 1, 2, 1]
Process ForkPoolWorker-6:
Traceback (most recent call last):
  File "/usr/lib64/python3.4/multiprocessing/process.py", line 254, in _bootstrap
    self.run()
  File "/usr/lib64/python3.4/multiprocessing/process.py", line 93, in run
    self._target(*self._args, **self._kwargs)
  File "/usr/lib64/python3.4/multiprocessing/pool.py", line 108, in worker
    task = get()
  File "/usr/lib64/python3.4/multiprocessing/queues.py", line 360, in get
    res = self._reader.recv_bytes()
  File "/usr/lib64/python3.4/multiprocessing/connection.py", line 216, in recv_bytes
    buf = self._recv_bytes(maxlength)
  File "/usr/lib64/python3.4/multiprocessing/connection.py", line 420, in _recv_bytes
    return self._recv(size)
  File "/usr/lib64/python3.4/multiprocessing/connection.py", line 392, in _recv
    buf.write(chunk)
MemoryError
--- Evolve in 648 possible combinations ---
Exception in thread Thread-1:
Traceback (most recent call last):
  File "/usr/lib64/python3.4/threading.py", line 911, in _bootstrap_inner
    self.run()
  File "/usr/lib64/python3.4/threading.py", line 859, in run
    self._target(*self._args, **self._kwargs)
  File "/usr/lib64/python3.4/multiprocessing/pool.py", line 366, in _handle_workers
    pool._maintain_pool()
  File "/usr/lib64/python3.4/multiprocessing/pool.py", line 240, in _maintain_pool
    self._repopulate_pool()
  File "/usr/lib64/python3.4/multiprocessing/pool.py", line 233, in _repopulate_pool
    w.start()
  File "/usr/lib64/python3.4/multiprocessing/process.py", line 105, in start
    self._popen = self._Popen(self)
  File "/usr/lib64/python3.4/multiprocessing/context.py", line 267, in _Popen
    return Popen(process_obj)
  File "/usr/lib64/python3.4/multiprocessing/popen_fork.py", line 21, in __init__
    self._launch(process_obj)
  File "/usr/lib64/python3.4/multiprocessing/popen_fork.py", line 70, in _launch
    self.pid = os.fork()
OSError: [Errno 12] Cannot allocate memory

Traceback (most recent call last):
  File "main.py", line 58, in <module>
    ev.fit(scoring='accuracy', n_jobs=cpu_count(), kargs=searchParams)
  File "/home/Manuel.Castillo/pruebasOHC/lib/ProcessManager.py", line 36, in fit
    agcv.fit(self.X, self.y)
  File "./lib/easSearch.py", line 200, in fit
    self._fit(X, y, self.params)
  File "./lib/easSearch.py", line 263, in _fit
    halloffame=hof, verbose=self.verbose)
  File "/usr/lib/python3.4/site-packages/deap/algorithms.py", line 150, in eaSimple
    fitnesses = toolbox.map(toolbox.evaluate, invalid_ind)
  File "/usr/lib64/python3.4/multiprocessing/pool.py", line 260, in map
    return self._map_async(func, iterable, mapstar, chunksize).get()
  File "/usr/lib64/python3.4/multiprocessing/pool.py", line 608, in get
    raise self._value
  File "/usr/lib64/python3.4/multiprocessing/pool.py", line 385, in _handle_tasks
    put(task)
  File "/usr/lib64/python3.4/multiprocessing/connection.py", line 206, in send
    self._send_bytes(ForkingPickler.dumps(obj))
  File "/usr/lib64/python3.4/multiprocessing/reduction.py", line 50, in dumps
    cls(buf, protocol).dump(obj)
MemoryError
Traceback (most recent call last):
  File "/usr/lib64/python3.4/multiprocessing/util.py", line 252, in _run_finalizers
    finalizer()
  File "/usr/lib64/python3.4/multiprocessing/util.py", line 185, in __call__
    res = self._callback(*self._args, **self._kwargs)
  File "/usr/lib64/python3.4/multiprocessing/pool.py", line 553, in _terminate_pool
    p.terminate()
  File "/usr/lib64/python3.4/multiprocessing/process.py", line 113, in terminate
    self._popen.terminate()
AttributeError: 'NoneType' object has no attribute 'terminate'
