/usr/lib/python3.4/site-packages/deap/tools/_hypervolume/pyhv.py:33: ImportWarning: Falling back to the python version of hypervolume module. Expect this to be very slow.
  "module. Expect this to be very slow.", ImportWarning)
multiprocessing.pool.RemoteTraceback: 
"""
Traceback (most recent call last):
  File "/usr/lib64/python3.4/multiprocessing/pool.py", line 119, in worker
    result = (True, func(*args, **kwds))
  File "/usr/lib64/python3.4/multiprocessing/pool.py", line 47, in starmapstar
    return list(itertools.starmap(args[0], args[1]))
  File "./lib/Methods.py", line 47, in getModelAccuracy
    params = _individual_to_params(individual, parametros)
  File "./lib/Methods.py", line 91, in _individual_to_params
    return dict((name, values[gene]) for gene, (name, values) in zip(individual, name_values))
  File "./lib/Methods.py", line 91, in <genexpr>
    return dict((name, values[gene]) for gene, (name, values) in zip(individual, name_values))
IndexError: list index out of range
"""

The above exception was the direct cause of the following exception:

Traceback (most recent call last):
  File "main.py", line 58, in <module>
    ev.fit(scoring='accuracy', n_jobs=cpu_count(), kargs=searchParams)
  File "/home/Manuel.Castillo/pruebasOHC/lib/ProcessManager.py", line 44, in fit
    edcv.run()
  File "./lib/edasSearch.py", line 105, in run
    self.evaluate()  # Multi process
  File "./lib/edasSearch.py", line 84, in evaluate
    self.sample[:, -1] = _pool.starmap(self.objective_function, _iterable)
  File "/usr/lib64/python3.4/multiprocessing/pool.py", line 268, in starmap
    return self._map_async(func, iterable, starmapstar, chunksize).get()
  File "/usr/lib64/python3.4/multiprocessing/pool.py", line 608, in get
    raise self._value
IndexError: list index out of range
